Workbook
Name SegmentaçãodeDados_Renew: #N/A
Name SegmentaçãodeDados_Subscription_Type: #N/A

Sheet A̳ssets
B3: Paleta de Cores
B5: # 9BC848 | C5: Xbox Color | E5: # E8E6E9 | F5: negative zone | J5: #224386 | K5: Side Background
B6: # 22C55E | C6: Xbox Color | J6: #E8E8E8 | K6: Negative Zone
B7: # 2AE6B1 | C7: Menus | J7: #2FE9FD | K7: Graphic
B8: # 5BF6A8 | C8: Menus | J8: #CDEAF7 | K8: Selected Item
B12: Logos | J12: ícones

Sheet B̳ases
A1: Subscriber ID | B1: Name | C1: Plan | D1: Start Date | E1: Auto Renewal | F1: Subscription Price | G1: Subscription Type | H1: EA Play Season Pass | I1: EA Play Season Pass Price | J1: Minecraft Season Pass | K1: Minecraft Season Pass Price | L1: Coupon Value | M1: Total Value | N1: Expiration_date | O1: Expiration | P1: Month | Q1: Renew
A2: 3231 | B2: João Silva | C2: Ultimate | D2: 45292 | E2: Yes | F2: 15 | G2: Monthly | H2: Yes | I2: 30 | J2: Yes | K2: 20 | L2: 5 | M2: 60 | N2: {=DATEVALUE(_xlfn.CONCAT("01/", MONTH(EDATE(Tb_Data[[#This Row],[Start Date]],_xlfn.IFS(Tb_Data[[#This Row],[Subscription Type]]="Monthly",1,Tb_Data[[#This Row],[Subscription Type]]="Annual",12,Tb_Data[[#This Row],[Subscription Type]]="Quarterly",3))),"/", YEAR(EDATE(Tb_Data[[#This Row],[Start Date]],_xlfn.IFS(Tb_Data[[#This Row],[Subscription Type]]="Monthly",1,Tb_Data[[#This Row],[Subscription Type]]="Annual",12,Tb_Data[[#This Row],[Subscription Type]]="Quarterly",3)))))} -> 45323 | O2: =IF(Tb_Data[[#This Row],[Expiration_date]]<C̳álculos!$I$6,"",Tb_Data[[#This Row],[Expiration_date]]) | P2: =DATEVALUE(_xlfn.CONCAT("01/",MONTH(Tb_Data[[#This Row],[Start Date]]),"/",YEAR(Tb_Data[[#This Row],[Start Date]]))) -> 45292 | Q2: =IF(Tb_Data[[#This Row],[Auto Renewal]]="yes","Auto","Manual") -> Auto
A3: 3232 | B3: Maria Oliveira | C3: Core | D3: 45306 | E3: No | F3: 5 | G3: Annual | H3: No | I3: - | J3: No | K3: 0 | L3: 0 | M3: 5 | N3: {=DATEVALUE(_xlfn.CONCAT("01/", MONTH(EDATE(Tb_Data[[#This Row],[Start Date]],_xlfn.IFS(Tb_Data[[#This Row],[Subscription Type]]="Monthly",1,Tb_Data[[#This Row],[Subscription Type]]="Annual",12,Tb_Data[[#This Row],[Subscription Type]]="Quarterly",3))),"/", YEAR(EDATE(Tb_Data[[#This Row],[Start Date]],_xlfn.IFS(Tb_Data[[#This Row],[Subscription Type]]="Monthly",1,Tb_Data[[#This Row],[Subscription Type]]="Annual",12,Tb_Data[[#This Row],[Subscription Type]]="Quarterly",3)))))} -> 45658 | O3: =IF(Tb_Data[[#This Row],[Expiration_date]]<C̳álculos!$I$6,"",Tb_Data[[#This Row],[Expiration_date]]) -> 45658 | P3: =DATEVALUE(_xlfn.CONCAT("01/",MONTH(Tb_Data[[#This Row],[Start Date]]),"/",YEAR(Tb_Data[[#This Row],[Start Date]]))) -> 45292 | Q3: =IF(Tb_Data[[#This Row],[Auto Renewal]]="yes","Auto","Manual") -> Manual
A4: 3233 | B4: Lucas Fernandes | C4: Standard | D4: 45332 | E4: Yes | F4: 10 | G4: Quarterly | H4: No | I4: - | J4: Yes | K4: 20 | L4: 10 | M4: 20 | N4: {=DATEVALUE(_xlfn.CONCAT("01/", MONTH(EDATE(Tb_Data[[#This Row],[Start Date]],_xlfn.IFS(Tb_Data[[#This Row],[Subscription Type]]="Monthly",1,Tb_Data[[#This Row],[Subscription Type]]="Annual",12,Tb_Data[[#This Row],[Subscription Type]]="Quarterly",3))),"/", YEAR(EDATE(Tb_Data[[#This Row],[Start Date]],_xlfn.IFS(Tb_Data[[#This Row],[Subscription Type]]="Monthly",1,Tb_Data[[#This Row],[Subscription Type]]="Annual",12,Tb_Data[[#This Row],[Subscription Type]]="Quarterly",3)))))} -> 45413 | O4: =IF(Tb_Data[[#This Row],[Expiration_date]]<C̳álculos!$I$6,"",Tb_Data[[#This Row],[Expiration_date]]) | P4: =DATEVALUE(_xlfn.CONCAT("01/",MONTH(Tb_Data[[#This Row],[Start Date]]),"/",YEAR(Tb_Data[[#This Row],[Start Date]]))) -> 45323 | Q4: =IF(Tb_Data[[#This Row],[Auto Renewal]]="yes","Auto","Manual") -> Auto
A5: 3234 | B5: Ana Souza | C5: Ultimate | D5: 45342 | E5: No | F5: 15 | G5: Monthly | H5: Yes | I5: 30 | J5: Yes | K5: 20 | L5: 3 | M5: 62 | N5: {=DATEVALUE(_xlfn.CONCAT("01/", MONTH(EDATE(Tb_Data[[#This Row],[Start Date]],_xlfn.IFS(Tb_Data[[#This Row],[Subscription Type]]="Monthly",1,Tb_Data[[#This Row],[Subscription Type]]="Annual",12,Tb_Data[[#This Row],[Subscription Type]]="Quarterly",3))),"/", YEAR(EDATE(Tb_Data[[#This Row],[Start Date]],_xlfn.IFS(Tb_Data[[#This Row],[Subscription Type]]="Monthly",1,Tb_Data[[#This Row],[Subscription Type]]="Annual",12,Tb_Data[[#This Row],[Subscription Type]]="Quarterly",3)))))} -> 45352 | O5: =IF(Tb_Data[[#This Row],[Expiration_date]]<C̳álculos!$I$6,"",Tb_Data[[#This Row],[Expiration_date]]) | P5: =DATEVALUE(_xlfn.CONCAT("01/",MONTH(Tb_Data[[#This Row],[Start Date]]),"/",YEAR(Tb_Data[[#This Row],[Start Date]]))) -> 45323 | Q5: =IF(Tb_Data[[#This Row],[Auto Renewal]]="yes","Auto","Manual") -> Manual
A6: 3235 | B6: Pedro Gonçalves | C6: Core | D6: 45356 | E6: Yes | F6: 5 | G6: Monthly | H6: No | I6: - | J6: No | K6: 0 | L6: 1 | M6: 4 | N6: {=DATEVALUE(_xlfn.CONCAT("01/", MONTH(EDATE(Tb_Data[[#This Row],[Start Date]],_xlfn.IFS(Tb_Data[[#This Row],[Subscription Type]]="Monthly",1,Tb_Data[[#This Row],[Subscription Type]]="Annual",12,Tb_Data[[#This Row],[Subscription Type]]="Quarterly",3))),"/", YEAR(EDATE(Tb_Data[[#This Row],[Start Date]],_xlfn.IFS(Tb_Data[[#This Row],[Subscription Type]]="Monthly",1,Tb_Data[[#This Row],[Subscription Type]]="Annual",12,Tb_Data[[#This Row],[Subscription Type]]="Quarterly",3)))))} -> 45383 | O6: =IF(Tb_Data[[#This Row],[Expiration_date]]<C̳álculos!$I$6,"",Tb_Data[[#This Row],[Expiration_date]]) | P6: =DATEVALUE(_xlfn.CONCAT("01/",MONTH(Tb_Data[[#This Row],[Start Date]]),"/",YEAR(Tb_Data[[#This Row],[Start Date]]))) -> 45352 | Q6: =IF(Tb_Data[[#This Row],[Auto Renewal]]="yes","Auto","Manual") -> Auto
A7: 3236 | B7: Felipe Costa | C7: Standard | D7: 45353 | E7: No | F7: 10 | G7: Monthly | H7: No | I7: - | J7: Yes | K7: 20 | L7: 2 | M7: 28 | N7: {=DATEVALUE(_xlfn.CONCAT("01/", MONTH(EDATE(Tb_Data[[#This Row],[Start Date]],_xlfn.IFS(Tb_Data[[#This Row],[Subscription Type]]="Monthly",1,Tb_Data[[#This Row],[Subscription Type]]="Annual",12,Tb_Data[[#This Row],[Subscription Type]]="Quarterly",3))),"/", YEAR(EDATE(Tb_Data[[#This Row],[Start Date]],_xlfn.IFS(Tb_Data[[#This Row],[Subscription Type]]="Monthly",1,Tb_Data[[#This Row],[Subscription Type]]="Annual",12,Tb_Data[[#This Row],[Subscription Type]]="Quarterly",3)))))} -> 45383 | O7: =IF(Tb_Data[[#This Row],[Expiration_date]]<C̳álculos!$I$6,"",Tb_Data[[#This Row],[Expiration_date]]) | P7: =DATEVALUE(_xlfn.CONCAT("01/",MONTH(Tb_Data[[#This Row],[Start Date]]),"/",YEAR(Tb_Data[[#This Row],[Start Date]]))) -> 45352 | Q7: =IF(Tb_Data[[#This Row],[Auto Renewal]]="yes","Auto","Manual") -> Manual
A8: 3237 | B8: Camila Ribeiro | C8: Ultimate | D8: 45354 | E8: Yes | F8: 15 | G8: Quarterly | H8: Yes | I8: 30 | J8: Yes | K8: 20 | L8: 10 | M8: 55 | N8: {=DATEVALUE(_xlfn.CONCAT("01/", MONTH(EDATE(Tb_Data[[#This Row],[Start Date]],_xlfn.IFS(Tb_Data[[#This Row],[Subscription Type]]="Monthly",1,Tb_Data[[#This Row],[Subscription Type]]="Annual",12,Tb_Data[[#This Row],[Subscription Type]]="Quarterly",3))),"/", YEAR(EDATE(Tb_Data[[#This Row],[Start Date]],_xlfn.IFS(Tb_Data[[#This Row],[Subscription Type]]="Monthly",1,Tb_Data[[#This Row],[Subscription Type]]="Annual",12,Tb_Data[[#This Row],[Subscription Type]]="Quarterly",3)))))} -> 45444 | O8: =IF(Tb_Data[[#This Row],[Expiration_date]]<C̳álculos!$I$6,"",Tb_Data[[#This Row],[Expiration_date]]) | P8: =DATEVALUE(_xlfn.CONCAT("01/",MONTH(Tb_Data[[#This Row],[Start Date]]),"/",YEAR(Tb_Data[[#This Row],[Start Date]]))) -> 45352 | Q8: =IF(Tb_Data[[#This Row],[Auto Renewal]]="yes","Auto","Manual") -> Auto
A9: 3238 | B9: André Mendes | C9: Core | D9: 45355 | E9: Yes | F9: 5 | G9: Annual | H9: No | I9: - | J9: No | K9: 0 | L9: 0 | M9: 5 | N9: {=DATEVALUE(_xlfn.CONCAT("01/", MONTH(EDATE(Tb_Data[[#This Row],[Start Date]],_xlfn.IFS(Tb_Data[[#This Row],[Subscription Type]]="Monthly",1,Tb_Data[[#This Row],[Subscription Type]]="Annual",12,Tb_Data[[#This Row],[Subscription Type]]="Quarterly",3))),"/", YEAR(EDATE(Tb_Data[[#This Row],[Start Date]],_xlfn.IFS(Tb_Data[[#This Row],[Subscription Type]]="Monthly",1,Tb_Data[[#This Row],[Subscription Type]]="Annual",12,Tb_Data[[#This Row],[Subscription Type]]="Quarterly",3)))))} -> 45717 | O9: =IF(Tb_Data[[#This Row],[Expiration_date]]<C̳álculos!$I$6,"",Tb_Data[[#This Row],[Expiration_date]]) -> 45717 | P9: =DATEVALUE(_xlfn.CONCAT("01/",MONTH(Tb_Data[[#This Row],[Start Date]]),"/",YEAR(Tb_Data[[#This Row],[Start Date]]))) -> 45352 | Q9: =IF(Tb_Data[[#This Row],[Auto Renewal]]="yes","Auto","Manual") -> Auto
A10: 3239 | B10: Sofia Almeida | C10: Ultimate | D10: 45356 | E10: No | F10: 15 | G10: Monthly | H10: Yes | I10: 30 | J10: Yes | K10: 20 | L10: 5 | M10: 60 | N10: {=DATEVALUE(_xlfn.CONCAT("01/", MONTH(EDATE(Tb_Data[[#This Row],[Start Date]],_xlfn.IFS(Tb_Data[[#This Row],[Subscription Type]]="Monthly",1,Tb_Data[[#This Row],[Subscription Type]]="Annual",12,Tb_Data[[#This Row],[Subscription Type]]="Quarterly",3))),"/", YEAR(EDATE(Tb_Data[[#This Row],[Start Date]],_xlfn.IFS(Tb_Data[[#This Row],[Subscription Type]]="Monthly",1,Tb_Data[[#This Row],[Subscription Type]]="Annual",12,Tb_Data[[#This Row],[Subscription Type]]="Quarterly",3)))))} -> 45383 | O10: =IF(Tb_Data[[#This Row],[Expiration_date]]<C̳álculos!$I$6,"",Tb_Data[[#This Row],[Expiration_date]]) | P10: =DATEVALUE(_xlfn.CONCAT("01/",MONTH(Tb_Data[[#This Row],[Start Date]]),"/",YEAR(Tb_Data[[#This Row],[Start Date]]))) -> 45352 | Q10: =IF(Tb_Data[[#This Row],[Auto Renewal]]="yes","Auto","Manual") -> Manual
A11: 3240 | B11: Bruno Martins | C11: Standard | D11: 45357 | E11: Yes | F11: 10 | G11: Quarterly | H11: No | I11: - | J11: Yes | K11: 20 | L11: 15 | M11: 15 | N11: {=DATEVALUE(_xlfn.CONCAT("01/", MONTH(EDATE(Tb_Data[[#This Row],[Start Date]],_xlfn.IFS(Tb_Data[[#This Row],[Subscription Type]]="Monthly",1,Tb_Data[[#This Row],[Subscription Type]]="Annual",12,Tb_Data[[#This Row],[Subscription Type]]="Quarterly",3))),"/", YEAR(EDATE(Tb_Data[[#This Row],[Start Date]],_xlfn.IFS(Tb_Data[[#This Row],[Subscription Type]]="Monthly",1,Tb_Data[[#This Row],[Subscription Type]]="Annual",12,Tb_Data[[#This Row],[Subscription Type]]="Quarterly",3)))))} -> 45444 | O11: =IF(Tb_Data[[#This Row],[Expiration_date]]<C̳álculos!$I$6,"",Tb_Data[[#This Row],[Expiration_date]]) | P11: =DATEVALUE(_xlfn.CONCAT("01/",MONTH(Tb_Data[[#This Row],[Start Date]]),"/",YEAR(Tb_Data[[#This Row],[Start Date]]))) -> 45352 | Q11: =IF(Tb_Data[[#This Row],[Auto Renewal]]="yes","Auto","Manual") -> Auto
A12: 3241 | B12: Rita Castro | C12: Core | D12: 45358 | E12: No | F12: 5 | G12: Monthly | H12: No | I12: - | J12: No | K12: 0 | L12: 1 | M12: 4 | N12: {=DATEVALUE(_xlfn.CONCAT("01/", MONTH(EDATE(Tb_Data[[#This Row],[Start Date]],_xlfn.IFS(Tb_Data[[#This Row],[Subscription Type]]="Monthly",1,Tb_Data[[#This Row],[Subscription Type]]="Annual",12,Tb_Data[[#This Row],[Subscription Type]]="Quarterly",3))),"/", YEAR(EDATE(Tb_Data[[#This Row],[Start Date]],_xlfn.IFS(Tb_Data[[#This Row],[Subscription Type]]="Monthly",1,Tb_Data[[#This Row],[Subscription Type]]="Annual",12,Tb_Data[[#This Row],[Subscription Type]]="Quarterly",3)))))} -> 45383 | O12: =IF(Tb_Data[[#This Row],[Expiration_date]]<C̳álculos!$I$6,"",Tb_Data[[#This Row],[Expiration_date]]) | P12: =DATEVALUE(_xlfn.CONCAT("01/",MONTH(Tb_Data[[#This Row],[Start Date]]),"/",YEAR(Tb_Data[[#This Row],[Start Date]]))) -> 45352 | Q12: =IF(Tb_Data[[#This Row],[Auto Renewal]]="yes","Auto","Manual") -> Manual
A13: 3242 | B13: Marco Túlio | C13: Ultimate | D13: 45359 | E13: Yes | F13: 15 | G13: Annual | H13: Yes | I13: 30 | J13: Yes | K13: 20 | L13: 20 | M13: 45 | N13: {=DATEVALUE(_xlfn.CONCAT("01/", MONTH(EDATE(Tb_Data[[#This Row],[Start Date]],_xlfn.IFS(Tb_Data[[#This Row],[Subscription Type]]="Monthly",1,Tb_Data[[#This Row],[Subscription Type]]="Annual",12,Tb_Data[[#This Row],[Subscription Type]]="Quarterly",3))),"/", YEAR(EDATE(Tb_Data[[#This Row],[Start Date]],_xlfn.IFS(Tb_Data[[#This Row],[Subscription Type]]="Monthly",1,Tb_Data[[#This Row],[Subscription Type]]="Annual",12,Tb_Data[[#This Row],[Subscription Type]]="Quarterly",3)))))} -> 45717 | O13: =IF(Tb_Data[[#This Row],[Expiration_date]]<C̳álculos!$I$6,"",Tb_Data[[#This Row],[Expiration_date]]) -> 45717 | P13: =DATEVALUE(_xlfn.CONCAT("01/",MONTH(Tb_Data[[#This Row],[Start Date]]),"/",YEAR(Tb_Data[[#This Row],[Start Date]]))) -> 45352 | Q13: =IF(Tb_Data[[#This Row],[Auto Renewal]]="yes","Auto","Manual") -> Auto
A14: 3243 | B14: Lívia Silveira | C14: Standard | D14: 45360 | E14: No | F14: 10 | G14: Monthly | H14: No | I14: - | J14: Yes | K14: 20 | L14: 10 | M14: 20 | N14: {=DATEVALUE(_xlfn.CONCAT("01/", MONTH(EDATE(Tb_Data[[#This Row],[Start Date]],_xlfn.IFS(Tb_Data[[#This Row],[Subscription Type]]="Monthly",1,Tb_Data[[#This Row],[Subscription Type]]="Annual",12,Tb_Data[[#This Row],[Subscription Type]]="Quarterly",3))),"/", YEAR(EDATE(Tb_Data[[#This Row],[Start Date]],_xlfn.IFS(Tb_Data[[#This Row],[Subscription Type]]="Monthly",1,Tb_Data[[#This Row],[Subscription Type]]="Annual",12,Tb_Data[[#This Row],[Subscription Type]]="Quarterly",3)))))} -> 45383 | O14: =IF(Tb_Data[[#This Row],[Expiration_date]]<C̳álculos!$I$6,"",Tb_Data[[#This Row],[Expiration_date]]) | P14: =DATEVALUE(_xlfn.CONCAT("01/",MONTH(Tb_Data[[#This Row],[Start Date]]),"/",YEAR(Tb_Data[[#This Row],[Start Date]]))) -> 45352 | Q14: =IF(Tb_Data[[#This Row],[Auto Renewal]]="yes","Auto","Manual") -> Manual
A15: 3244 | B15: Diogo Sousa | C15: Core | D15: 45361 | E15: Yes | F15: 5 | G15: Quarterly | H15: No | I15: - | J15: No | K15: 0 | L15: 0 | M15: 5 | N15: {=DATEVALUE(_xlfn.CONCAT("01/", MONTH(EDATE(Tb_Data[[#This Row],[Start Date]],_xlfn.IFS(Tb_Data[[#This Row],[Subscription Type]]="Monthly",1,Tb_Data[[#This Row],[Subscription Type]]="Annual",12,Tb_Data[[#This Row],[Subscription Type]]="Quarterly",3))),"/", YEAR(EDATE(Tb_Data[[#This Row],[Start Date]],_xlfn.IFS(Tb_Data[[#This Row],[Subscription Type]]="Monthly",1,Tb_Data[[#This Row],[Subscription Type]]="Annual",12,Tb_Data[[#This Row],[Subscription Type]]="Quarterly",3)))))} -> 45444 | O15: =IF(Tb_Data[[#This Row],[Expiration_date]]<C̳álculos!$I$6,"",Tb_Data[[#This Row],[Expiration_date]]) | P15: =DATEVALUE(_xlfn.CONCAT("01/",MONTH(Tb_Data[[#This Row],[Start Date]]),"/",YEAR(Tb_Data[[#This Row],[Start Date]]))) -> 45352 | Q15: =IF(Tb_Data[[#This Row],[Auto Renewal]]="yes","Auto","Manual") -> Auto
A16: 3245 | B16: Fernanda Lima | C16: Ultimate | D16: 45362 | E16: No | F16: 15 | G16: Monthly | H16: Yes | I16: 30 | J16: Yes | K16: 20 | L16: 8 | M16: 57 | N16: {=DATEVALUE(_xlfn.CONCAT("01/", MONTH(EDATE(Tb_Data[[#This Row],[Start Date]],_xlfn.IFS(Tb_Data[[#This Row],[Subscription Type]]="Monthly",1,Tb_Data[[#This Row],[Subscription Type]]="Annual",12,Tb_Data[[#This Row],[Subscription Type]]="Quarterly",3))),"/", YEAR(EDATE(Tb_Data[[#This Row],[Start Date]],_xlfn.IFS(Tb_Data[[#This Row],[Subscription Type]]="Monthly",1,Tb_Data[[#This Row],[Subscription Type]]="Annual",12,Tb_Data[[#This Row],[Subscription Type]]="Quarterly",3)))))} -> 45383 | O16: =IF(Tb_Data[[#This Row],[Expiration_date]]<C̳álculos!$I$6,"",Tb_Data[[#This Row],[Expiration_date]]) | P16: =DATEVALUE(_xlfn.CONCAT("01/",MONTH(Tb_Data[[#This Row],[Start Date]]),"/",YEAR(Tb_Data[[#This Row],[Start Date]]))) -> 45352 | Q16: =IF(Tb_Data[[#This Row],[Auto Renewal]]="yes","Auto","Manual") -> Manual
A17: 3246 | B17: Caio Pereira | C17: Standard | D17: 45363 | E17: Yes | F17: 10 | G17: Annual | H17: No | I17: - | J17: Yes | K17: 20 | L17: 12 | M17: 18 | N17: {=DATEVALUE(_xlfn.CONCAT("01/", MONTH(EDATE(Tb_Data[[#This Row],[Start Date]],_xlfn.IFS(Tb_Data[[#This Row],[Subscription Type]]="Monthly",1,Tb_Data[[#This Row],[Subscription Type]]="Annual",12,Tb_Data[[#This Row],[Subscription Type]]="Quarterly",3))),"/", YEAR(EDATE(Tb_Data[[#This Row],[Start Date]],_xlfn.IFS(Tb_Data[[#This Row],[Subscription Type]]="Monthly",1,Tb_Data[[#This Row],[Subscription Type]]="Annual",12,Tb_Data[[#This Row],[Subscription Type]]="Quarterly",3)))))} -> 45717 | O17: =IF(Tb_Data[[#This Row],[Expiration_date]]<C̳álculos!$I$6,"",Tb_Data[[#This Row],[Expiration_date]]) -> 45717 | P17: =DATEVALUE(_xlfn.CONCAT("01/",MONTH(Tb_Data[[#This Row],[Start Date]]),"/",YEAR(Tb_Data[[#This Row],[Start Date]]))) -> 45352 | Q17: =IF(Tb_Data[[#This Row],[Auto Renewal]]="yes","Auto","Manual") -> Auto
A18: 3247 | B18: Beatriz Gomes | C18: Core | D18: 45364 | E18: No | F18: 5 | G18: Monthly | H18: No | I18: - | J18: No | K18: 0 | L18: 2 | M18: 3 | N18: {=DATEVALUE(_xlfn.CONCAT("01/", MONTH(EDATE(Tb_Data[[#This Row],[Start Date]],_xlfn.IFS(Tb_Data[[#This Row],[Subscription Type]]="Monthly",1,Tb_Data[[#This Row],[Subscription Type]]="Annual",12,Tb_Data[[#This Row],[Subscription Type]]="Quarterly",3))),"/", YEAR(EDATE(Tb_Data[[#This Row],[Start Date]],_xlfn.IFS(Tb_Data[[#This Row],[Subscription Type]]="Monthly",1,Tb_Data[[#This Row],[Subscription Type]]="Annual",12,Tb_Data[[#This Row],[Subscription Type]]="Quarterly",3)))))} -> 45383 | O18: =IF(Tb_Data[[#This Row],[Expiration_date]]<C̳álculos!$I$6,"",Tb_Data[[#This Row],[Expiration_date]]) | P18: =DATEVALUE(_xlfn.CONCAT("01/",MONTH(Tb_Data[[#This Row],[Start Date]]),"/",YEAR(Tb_Data[[#This Row],[Start Date]]))) -> 45352 | Q18: =IF(Tb_Data[[#This Row],[Auto Renewal]]="yes","Auto","Manual") -> Manual
A19: 3248 | B19: Cesar Oliveira | C19: Ultimate | D19: 45365 | E19: Yes | F19: 15 | G19: Quarterly | H19: Yes | I19: 30 | J19: Yes | K19: 20 | L19: 7 | M19: 58 | N19: {=DATEVALUE(_xlfn.CONCAT("01/", MONTH(EDATE(Tb_Data[[#This Row],[Start Date]],_xlfn.IFS(Tb_Data[[#This Row],[Subscription Type]]="Monthly",1,Tb_Data[[#This Row],[Subscription Type]]="Annual",12,Tb_Data[[#This Row],[Subscription Type]]="Quarterly",3))),"/", YEAR(EDATE(Tb_Data[[#This Row],[Start Date]],_xlfn.IFS(Tb_Data[[#This Row],[Subscription Type]]="Monthly",1,Tb_Data[[#This Row],[Subscription Type]]="Annual",12,Tb_Data[[#This Row],[Subscription Type]]="Quarterly",3)))))} -> 45444 | O19: =IF(Tb_Data[[#This Row],[Expiration_date]]<C̳álculos!$I$6,"",Tb_Data[[#This Row],[Expiration_date]]) | P19: =DATEVALUE(_xlfn.CONCAT("01/",MONTH(Tb_Data[[#This Row],[Start Date]]),"/",YEAR(Tb_Data[[#This Row],[Start Date]]))) -> 45352 | Q19: =IF(Tb_Data[[#This Row],[Auto Renewal]]="yes","Auto","Manual") -> Auto
A20: 3249 | B20: Débora Machado | C20: Standard | D20: 45366 | E20: No | F20: 10 | G20: Monthly | H20: No | I20: - | J20: Yes | K20: 20 | L20: 5 | M20: 25 | N20: {=DATEVALUE(_xlfn.CONCAT("01/", MONTH(EDATE(Tb_Data[[#This Row],[Start Date]],_xlfn.IFS(Tb_Data[[#This Row],[Subscription Type]]="Monthly",1,Tb_Data[[#This Row],[Subscription Type]]="Annual",12,Tb_Data[[#This Row],[Subscription Type]]="Quarterly",3))),"/", YEAR(EDATE(Tb_Data[[#This Row],[Start Date]],_xlfn.IFS(Tb_Data[[#This Row],[Subscription Type]]="Monthly",1,Tb_Data[[#This Row],[Subscription Type]]="Annual",12,Tb_Data[[#This Row],[Subscription Type]]="Quarterly",3)))))} -> 45383 | O20: =IF(Tb_Data[[#This Row],[Expiration_date]]<C̳álculos!$I$6,"",Tb_Data[[#This Row],[Expiration_date]]) | P20: =DATEVALUE(_xlfn.CONCAT("01/",MONTH(Tb_Data[[#This Row],[Start Date]]),"/",YEAR(Tb_Data[[#This Row],[Start Date]]))) -> 45352 | Q20: =IF(Tb_Data[[#This Row],[Auto Renewal]]="yes","Auto","Manual") -> Manual
A21: 3250 | B21: Eduardo Vargas | C21: Core | D21: 45367 | E21: Yes | F21: 5 | G21: Annual | H21: No | I21: - | J21: No | K21: 0 | L21: 0 | M21: 5 | N21: {=DATEVALUE(_xlfn.CONCAT("01/", MONTH(EDATE(Tb_Data[[#This Row],[Start Date]],_xlfn.IFS(Tb_Data[[#This Row],[Subscription Type]]="Monthly",1,Tb_Data[[#This Row],[Subscription Type]]="Annual",12,Tb_Data[[#This Row],[Subscription Type]]="Quarterly",3))),"/", YEAR(EDATE(Tb_Data[[#This Row],[Start Date]],_xlfn.IFS(Tb_Data[[#This Row],[Subscription Type]]="Monthly",1,Tb_Data[[#This Row],[Subscription Type]]="Annual",12,Tb_Data[[#This Row],[Subscription Type]]="Quarterly",3)))))} -> 45717 | O21: =IF(Tb_Data[[#This Row],[Expiration_date]]<C̳álculos!$I$6,"",Tb_Data[[#This Row],[Expiration_date]]) -> 45717 | P21: =DATEVALUE(_xlfn.CONCAT("01/",MONTH(Tb_Data[[#This Row],[Start Date]]),"/",YEAR(Tb_Data[[#This Row],[Start Date]]))) -> 45352 | Q21: =IF(Tb_Data[[#This Row],[Auto Renewal]]="yes","Auto","Manual") -> Auto
A22: 3251 | B22: Gabriela Santos | C22: Ultimate | D22: 45368 | E22: No | F22: 15 | G22: Monthly | H22: Yes | I22: 30 | J22: Yes | K22: 20 | L22: 3 | M22: 62 | N22: {=DATEVALUE(_xlfn.CONCAT("01/", MONTH(EDATE(Tb_Data[[#This Row],[Start Date]],_xlfn.IFS(Tb_Data[[#This Row],[Subscription Type]]="Monthly",1,Tb_Data[[#This Row],[Subscription Type]]="Annual",12,Tb_Data[[#This Row],[Subscription Type]]="Quarterly",3))),"/", YEAR(EDATE(Tb_Data[[#This Row],[Start Date]],_xlfn.IFS(Tb_Data[[#This Row],[Subscription Type]]="Monthly",1,Tb_Data[[#This Row],[Subscription Type]]="Annual",12,Tb_Data[[#This Row],[Subscription Type]]="Quarterly",3)))))} -> 45383 | O22: =IF(Tb_Data[[#This Row],[Expiration_date]]<C̳álculos!$I$6,"",Tb_Data[[#This Row],[Expiration_date]]) | P22: =DATEVALUE(_xlfn.CONCAT("01/",MONTH(Tb_Data[[#This Row],[Start Date]]),"/",YEAR(Tb_Data[[#This Row],[Start Date]]))) -> 45352 | Q22: =IF(Tb_Data[[#This Row],[Auto Renewal]]="yes","Auto","Manual") -> Manual
A23: 3252 | B23: Henrique Dias | C23: Standard | D23: 45369 | E23: Yes | F23: 10 | G23: Quarterly | H23: No | I23: - | J23: Yes | K23: 20 | L23: 15 | M23: 15 | N23: {=DATEVALUE(_xlfn.CONCAT("01/", MONTH(EDATE(Tb_Data[[#This Row],[Start Date]],_xlfn.IFS(Tb_Data[[#This Row],[Subscription Type]]="Monthly",1,Tb_Data[[#This Row],[Subscription Type]]="Annual",12,Tb_Data[[#This Row],[Subscription Type]]="Quarterly",3))),"/", YEAR(EDATE(Tb_Data[[#This Row],[Start Date]],_xlfn.IFS(Tb_Data[[#This Row],[Subscription Type]]="Monthly",1,Tb_Data[[#This Row],[Subscription Type]]="Annual",12,Tb_Data[[#This Row],[Subscription Type]]="Quarterly",3)))))} -> 45444 | O23: =IF(Tb_Data[[#This Row],[Expiration_date]]<C̳álculos!$I$6,"",Tb_Data[[#This Row],[Expiration_date]]) | P23: =DATEVALUE(_xlfn.CONCAT("01/",MONTH(Tb_Data[[#This Row],[Start Date]]),"/",YEAR(Tb_Data[[#This Row],[Start Date]]))) -> 45352 | Q23: =IF(Tb_Data[[#This Row],[Auto Renewal]]="yes","Auto","Manual") -> Auto
A24: 3253 | B24: Isabela Moreira | C24: Core | D24: 45370 | E24: No | F24: 5 | G24: Monthly | H24: No | I24: - | J24: No | K24: 0 | L24: 1 | M24: 4 | N24: {=DATEVALUE(_xlfn.CONCAT("01/", MONTH(EDATE(Tb_Data[[#This Row],[Start Date]],_xlfn.IFS(Tb_Data[[#This Row],[Subscription Type]]="Monthly",1,Tb_Data[[#This Row],[Subscription Type]]="Annual",12,Tb_Data[[#This Row],[Subscription Type]]="Quarterly",3))),"/", YEAR(EDATE(Tb_Data[[#This Row],[Start Date]],_xlfn.IFS(Tb_Data[[#This Row],[Subscription Type]]="Monthly",1,Tb_Data[[#This Row],[Subscription Type]]="Annual",12,Tb_Data[[#This Row],[Subscription Type]]="Quarterly",3)))))} -> 45383 | O24: =IF(Tb_Data[[#This Row],[Expiration_date]]<C̳álculos!$I$6,"",Tb_Data[[#This Row],[Expiration_date]]) | P24: =DATEVALUE(_xlfn.CONCAT("01/",MONTH(Tb_Data[[#This Row],[Start Date]]),"/",YEAR(Tb_Data[[#This Row],[Start Date]]))) -> 45352 | Q24: =IF(Tb_Data[[#This Row],[Auto Renewal]]="yes","Auto","Manual") -> Manual
A25: 3254 | B25: Joaquim Barbosa | C25: Ultimate | D25: 45371 | E25: Yes | F25: 15 | G25: Annual | H25: Yes | I25: 30 | J25: Yes | K25: 20 | L25: 20 | M25: 45 | N25: {=DATEVALUE(_xlfn.CONCAT("01/", MONTH(EDATE(Tb_Data[[#This Row],[Start Date]],_xlfn.IFS(Tb_Data[[#This Row],[Subscription Type]]="Monthly",1,Tb_Data[[#This Row],[Subscription Type]]="Annual",12,Tb_Data[[#This Row],[Subscription Type]]="Quarterly",3))),"/", YEAR(EDATE(Tb_Data[[#This Row],[Start Date]],_xlfn.IFS(Tb_Data[[#This Row],[Subscription Type]]="Monthly",1,Tb_Data[[#This Row],[Subscription Type]]="Annual",12,Tb_Data[[#This Row],[Subscription Type]]="Quarterly",3)))))} -> 45717 | O25: =IF(Tb_Data[[#This Row],[Expiration_date]]<C̳álculos!$I$6,"",Tb_Data[[#This Row],[Expiration_date]]) -> 45717 | P25: =DATEVALUE(_xlfn.CONCAT("01/",MONTH(Tb_Data[[#This Row],[Start Date]]),"/",YEAR(Tb_Data[[#This Row],[Start Date]]))) -> 45352 | Q25: =IF(Tb_Data[[#This Row],[Auto Renewal]]="yes","Auto","Manual") -> Auto
A26: 3255 | B26: Lara Rocha | C26: Standard | D26: 45372 | E26: No | F26: 10 | G26: Monthly | H26: No | I26: - | J26: Yes | K26: 20 | L26: 10 | M26: 20 | N26: {=DATEVALUE(_xlfn.CONCAT("01/", MONTH(EDATE(Tb_Data[[#This Row],[Start Date]],_xlfn.IFS(Tb_Data[[#This Row],[Subscription Type]]="Monthly",1,Tb_Data[[#This Row],[Subscription Type]]="Annual",12,Tb_Data[[#This Row],[Subscription Type]]="Quarterly",3))),"/", YEAR(EDATE(Tb_Data[[#This Row],[Start Date]],_xlfn.IFS(Tb_Data[[#This Row],[Subscription Type]]="Monthly",1,Tb_Data[[#This Row],[Subscription Type]]="Annual",12,Tb_Data[[#This Row],[Subscription Type]]="Quarterly",3)))))} -> 45383 | O26: =IF(Tb_Data[[#This Row],[Expiration_date]]<C̳álculos!$I$6,"",Tb_Data[[#This Row],[Expiration_date]]) | P26: =DATEVALUE(_xlfn.CONCAT("01/",MONTH(Tb_Data[[#This Row],[Start Date]]),"/",YEAR(Tb_Data[[#This Row],[Start Date]]))) -> 45352 | Q26: =IF(Tb_Data[[#This Row],[Auto Renewal]]="yes","Auto","Manual") -> Manual
A27: 3256 | B27: Matheus Silva | C27: Core | D27: 45373 | E27: Yes | F27: 5 | G27: Quarterly | H27: No | I27: - | J27: No | K27: 0 | L27: 0 | M27: 5 | N27: {=DATEVALUE(_xlfn.CONCAT("01/", MONTH(EDATE(Tb_Data[[#This Row],[Start Date]],_xlfn.IFS(Tb_Data[[#This Row],[Subscription Type]]="Monthly",1,Tb_Data[[#This Row],[Subscription Type]]="Annual",12,Tb_Data[[#This Row],[Subscription Type]]="Quarterly",3))),"/", YEAR(EDATE(Tb_Data[[#This Row],[Start Date]],_xlfn.IFS(Tb_Data[[#This Row],[Subscription Type]]="Monthly",1,Tb_Data[[#This Row],[Subscription Type]]="Annual",12,Tb_Data[[#This Row],[Subscription Type]]="Quarterly",3)))))} -> 45444 | O27: =IF(Tb_Data[[#This Row],[Expiration_date]]<C̳álculos!$I$6,"",Tb_Data[[#This Row],[Expiration_date]]) | P27: =DATEVALUE(_xlfn.CONCAT("01/",MONTH(Tb_Data[[#This Row],[Start Date]]),"/",YEAR(Tb_Data[[#This Row],[Start Date]]))) -> 45352 | Q27: =IF(Tb_Data[[#This Row],[Auto Renewal]]="yes","Auto","Manual") -> Auto
A28: 3257 | B28: Nicole Costa | C28: Ultimate | D28: 45374 | E28: No | F28: 15 | G28: Monthly | H28: Yes | I28: 30 | J28: Yes | K28: 20 | L28: 5 | M28: 60 | N28: {=DATEVALUE(_xlfn.CONCAT("01/", MONTH(EDATE(Tb_Data[[#This Row],[Start Date]],_xlfn.IFS(Tb_Data[[#This Row],[Subscription Type]]="Monthly",1,Tb_Data[[#This Row],[Subscription Type]]="Annual",12,Tb_Data[[#This Row],[Subscription Type]]="Quarterly",3))),"/", YEAR(EDATE(Tb_Data[[#This Row],[Start Date]],_xlfn.IFS(Tb_Data[[#This Row],[Subscription Type]]="Monthly",1,Tb_Data[[#This Row],[Subscription Type]]="Annual",12,Tb_Data[[#This Row],[Subscription Type]]="Quarterly",3)))))} -> 45383 | O28: =IF(Tb_Data[[#This Row],[Expiration_date]]<C̳álculos!$I$6,"",Tb_Data[[#This Row],[Expiration_date]]) | P28: =DATEVALUE(_xlfn.CONCAT("01/",MONTH(Tb_Data[[#This Row],[Start Date]]),"/",YEAR(Tb_Data[[#This Row],[Start Date]]))) -> 45352 | Q28: =IF(Tb_Data[[#This Row],[Auto Renewal]]="yes","Auto","Manual") -> Manual
A29: 3258 | B29: Otávio Mendonça | C29: Standard | D29: 45375 | E29: Yes | F29: 10 | G29: Annual | H29: No | I29: - | J29: Yes | K29: 20 | L29: 15 | M29: 15 | N29: {=DATEVALUE(_xlfn.CONCAT("01/", MONTH(EDATE(Tb_Data[[#This Row],[Start Date]],_xlfn.IFS(Tb_Data[[#This Row],[Subscription Type]]="Monthly",1,Tb_Data[[#This Row],[Subscription Type]]="Annual",12,Tb_Data[[#This Row],[Subscription Type]]="Quarterly",3))),"/", YEAR(EDATE(Tb_Data[[#This Row],[Start Date]],_xlfn.IFS(Tb_Data[[#This Row],[Subscription Type]]="Monthly",1,Tb_Data[[#This Row],[Subscription Type]]="Annual",12,Tb_Data[[#This Row],[Subscription Type]]="Quarterly",3)))))} -> 45717 | O29: =IF(Tb_Data[[#This Row],[Expiration_date]]<C̳álculos!$I$6,"",Tb_Data[[#This Row],[Expiration_date]]) -> 45717 | P29: =DATEVALUE(_xlfn.CONCAT("01/",MONTH(Tb_Data[[#This Row],[Start Date]]),"/",YEAR(Tb_Data[[#This Row],[Start Date]]))) -> 45352 | Q29: =IF(Tb_Data[[#This Row],[Auto Renewal]]="yes","Auto","Manual") -> Auto
A30: 3259 | B30: Paula Ferreira | C30: Core | D30: 45376 | E30: No | F30: 5 | G30: Monthly | H30: No | I30: - | J30: No | K30: 0 | L30: 1 | M30: 4 | N30: {=DATEVALUE(_xlfn.CONCAT("01/", MONTH(EDATE(Tb_Data[[#This Row],[Start Date]],_xlfn.IFS(Tb_Data[[#This Row],[Subscription Type]]="Monthly",1,Tb_Data[[#This Row],[Subscription Type]]="Annual",12,Tb_Data[[#This Row],[Subscription Type]]="Quarterly",3))),"/", YEAR(EDATE(Tb_Data[[#This Row],[Start Date]],_xlfn.IFS(Tb_Data[[#This Row],[Subscription Type]]="Monthly",1,Tb_Data[[#This Row],[Subscription Type]]="Annual",12,Tb_Data[[#This Row],[Subscription Type]]="Quarterly",3)))))} -> 45383 | O30: =IF(Tb_Data[[#This Row],[Expiration_date]]<C̳álculos!$I$6,"",Tb_Data[[#This Row],[Expiration_date]]) | P30: =DATEVALUE(_xlfn.CONCAT("01/",MONTH(Tb_Data[[#This Row],[Start Date]]),"/",YEAR(Tb_Data[[#This Row],[Start Date]]))) -> 45352 | Q30: =IF(Tb_Data[[#This Row],[Auto Renewal]]="yes","Auto","Manual") -> Manual
A31: 3260 | B31: Raquel Alves | C31: Ultimate | D31: 45377 | E31: Yes | F31: 15 | G31: Quarterly | H31: Yes | I31: 30 | J31: Yes | K31: 20 | L31: 7 | M31: 58 | N31: {=DATEVALUE(_xlfn.CONCAT("01/", MONTH(EDATE(Tb_Data[[#This Row],[Start Date]],_xlfn.IFS(Tb_Data[[#This Row],[Subscription Type]]="Monthly",1,Tb_Data[[#This Row],[Subscription Type]]="Annual",12,Tb_Data[[#This Row],[Subscription Type]]="Quarterly",3))),"/", YEAR(EDATE(Tb_Data[[#This Row],[Start Date]],_xlfn.IFS(Tb_Data[[#This Row],[Subscription Type]]="Monthly",1,Tb_Data[[#This Row],[Subscription Type]]="Annual",12,Tb_Data[[#This Row],[Subscription Type]]="Quarterly",3)))))} -> 45444 | O31: =IF(Tb_Data[[#This Row],[Expiration_date]]<C̳álculos!$I$6,"",Tb_Data[[#This Row],[Expiration_date]]) | P31: =DATEVALUE(_xlfn.CONCAT("01/",MONTH(Tb_Data[[#This Row],[Start Date]]),"/",YEAR(Tb_Data[[#This Row],[Start Date]]))) -> 45352 | Q31: =IF(Tb_Data[[#This Row],[Auto Renewal]]="yes","Auto","Manual") -> Auto
A32: 3261 | B32: Samuel Pires | C32: Standard | D32: 45378 | E32: No | F32: 10 | G32: Monthly | H32: No | I32: - | J32: Yes | K32: 20 | L32: 10 | M32: 20 | N32: {=DATEVALUE(_xlfn.CONCAT("01/", MONTH(EDATE(Tb_Data[[#This Row],[Start Date]],_xlfn.IFS(Tb_Data[[#This Row],[Subscription Type]]="Monthly",1,Tb_Data[[#This Row],[Subscription Type]]="Annual",12,Tb_Data[[#This Row],[Subscription Type]]="Quarterly",3))),"/", YEAR(EDATE(Tb_Data[[#This Row],[Start Date]],_xlfn.IFS(Tb_Data[[#This Row],[Subscription Type]]="Monthly",1,Tb_Data[[#This Row],[Subscription Type]]="Annual",12,Tb_Data[[#This Row],[Subscription Type]]="Quarterly",3)))))} -> 45383 | O32: =IF(Tb_Data[[#This Row],[Expiration_date]]<C̳álculos!$I$6,"",Tb_Data[[#This Row],[Expiration_date]]) | P32: =DATEVALUE(_xlfn.CONCAT("01/",MONTH(Tb_Data[[#This Row],[Start Date]]),"/",YEAR(Tb_Data[[#This Row],[Start Date]]))) -> 45352 | Q32: =IF(Tb_Data[[#This Row],[Auto Renewal]]="yes","Auto","Manual") -> Manual
A33: 3262 | B33: Tânia Barros | C33: Core | D33: 45379 | E33: Yes | F33: 5 | G33: Annual | H33: No | I33: - | J33: No | K33: 0 | L33: 0 | M33: 5 | N33: {=DATEVALUE(_xlfn.CONCAT("01/", MONTH(EDATE(Tb_Data[[#This Row],[Start Date]],_xlfn.IFS(Tb_Data[[#This Row],[Subscription Type]]="Monthly",1,Tb_Data[[#This Row],[Subscription Type]]="Annual",12,Tb_Data[[#This Row],[Subscription Type]]="Quarterly",3))),"/", YEAR(EDATE(Tb_Data[[#This Row],[Start Date]],_xlfn.IFS(Tb_Data[[#This Row],[Subscription Type]]="Monthly",1,Tb_Data[[#This Row],[Subscription Type]]="Annual",12,Tb_Data[[#This Row],[Subscription Type]]="Quarterly",3)))))} -> 45717 | O33: =IF(Tb_Data[[#This Row],[Expiration_date]]<C̳álculos!$I$6,"",Tb_Data[[#This Row],[Expiration_date]]) -> 45717 | P33: =DATEVALUE(_xlfn.CONCAT("01/",MONTH(Tb_Data[[#This Row],[Start Date]]),"/",YEAR(Tb_Data[[#This Row],[Start Date]]))) -> 45352 | Q33: =IF(Tb_Data[[#This Row],[Auto Renewal]]="yes","Auto","Manual") -> Auto
A34: 3263 | B34: Vinicius Lima | C34: Ultimate | D34: 45380 | E34: No | F34: 15 | G34: Monthly | H34: Yes | I34: 30 | J34: Yes | K34: 20 | L34: 3 | M34: 62 | N34: {=DATEVALUE(_xlfn.CONCAT("01/", MONTH(EDATE(Tb_Data[[#This Row],[Start Date]],_xlfn.IFS(Tb_Data[[#This Row],[Subscription Type]]="Monthly",1,Tb_Data[[#This Row],[Subscription Type]]="Annual",12,Tb_Data[[#This Row],[Subscription Type]]="Quarterly",3))),"/", YEAR(EDATE(Tb_Data[[#This Row],[Start Date]],_xlfn.IFS(Tb_Data[[#This Row],[Subscription Type]]="Monthly",1,Tb_Data[[#This Row],[Subscription Type]]="Annual",12,Tb_Data[[#This Row],[Subscription Type]]="Quarterly",3)))))} -> 45383 | O34: =IF(Tb_Data[[#This Row],[Expiration_date]]<C̳álculos!$I$6,"",Tb_Data[[#This Row],[Expiration_date]]) | P34: =DATEVALUE(_xlfn.CONCAT("01/",MONTH(Tb_Data[[#This Row],[Start Date]]),"/",YEAR(Tb_Data[[#This Row],[Start Date]]))) -> 45352 | Q34: =IF(Tb_Data[[#This Row],[Auto Renewal]]="yes","Auto","Manual") -> Manual
A35: 3264 | B35: Yasmin Teixeira | C35: Standard | D35: 45381 | E35: Yes | F35: 10 | G35: Quarterly | H35: No | I35: - | J35: Yes | K35: 20 | L35: 15 | M35: 15 | N35: {=DATEVALUE(_xlfn.CONCAT("01/", MONTH(EDATE(Tb_Data[[#This Row],[Start Date]],_xlfn.IFS(Tb_Data[[#This Row],[Subscription Type]]="Monthly",1,Tb_Data[[#This Row],[Subscription Type]]="Annual",12,Tb_Data[[#This Row],[Subscription Type]]="Quarterly",3))),"/", YEAR(EDATE(Tb_Data[[#This Row],[Start Date]],_xlfn.IFS(Tb_Data[[#This Row],[Subscription Type]]="Monthly",1,Tb_Data[[#This Row],[Subscription Type]]="Annual",12,Tb_Data[[#This Row],[Subscription Type]]="Quarterly",3)))))} -> 45444 | O35: =IF(Tb_Data[[#This Row],[Expiration_date]]<C̳álculos!$I$6,"",Tb_Data[[#This Row],[Expiration_date]]) | P35: =DATEVALUE(_xlfn.CONCAT("01/",MONTH(Tb_Data[[#This Row],[Start Date]]),"/",YEAR(Tb_Data[[#This Row],[Start Date]]))) -> 45352 | Q35: =IF(Tb_Data[[#This Row],[Auto Renewal]]="yes","Auto","Manual") -> Auto
A36: 3265 | B36: Zé Carlos | C36: Core | D36: 45382 | E36: No | F36: 5 | G36: Monthly | H36: No | I36: - | J36: No | K36: 0 | L36: 1 | M36: 4 | N36: {=DATEVALUE(_xlfn.CONCAT("01/", MONTH(EDATE(Tb_Data[[#This Row],[Start Date]],_xlfn.IFS(Tb_Data[[#This Row],[Subscription Type]]="Monthly",1,Tb_Data[[#This Row],[Subscription Type]]="Annual",12,Tb_Data[[#This Row],[Subscription Type]]="Quarterly",3))),"/", YEAR(EDATE(Tb_Data[[#This Row],[Start Date]],_xlfn.IFS(Tb_Data[[#This Row],[Subscription Type]]="Monthly",1,Tb_Data[[#This Row],[Subscription Type]]="Annual",12,Tb_Data[[#This Row],[Subscription Type]]="Quarterly",3)))))} -> 45383 | O36: =IF(Tb_Data[[#This Row],[Expiration_date]]<C̳álculos!$I$6,"",Tb_Data[[#This Row],[Expiration_date]]) | P36: =DATEVALUE(_xlfn.CONCAT("01/",MONTH(Tb_Data[[#This Row],[Start Date]]),"/",YEAR(Tb_Data[[#This Row],[Start Date]]))) -> 45352 | Q36: =IF(Tb_Data[[#This Row],[Auto Renewal]]="yes","Auto","Manual") -> Manual
A37: 3266 | B37: Amanda Nogueira | C37: Core | D37: 45383 | E37: Yes | F37: 5 | G37: Monthly | H37: No | I37: - | J37: No | K37: 0 | L37: 0 | M37: 5 | N37: {=DATEVALUE(_xlfn.CONCAT("01/", MONTH(EDATE(Tb_Data[[#This Row],[Start Date]],_xlfn.IFS(Tb_Data[[#This Row],[Subscription Type]]="Monthly",1,Tb_Data[[#This Row],[Subscription Type]]="Annual",12,Tb_Data[[#This Row],[Subscription Type]]="Quarterly",3))),"/", YEAR(EDATE(Tb_Data[[#This Row],[Start Date]],_xlfn.IFS(Tb_Data[[#This Row],[Subscription Type]]="Monthly",1,Tb_Data[[#This Row],[Subscription Type]]="Annual",12,Tb_Data[[#This Row],[Subscription Type]]="Quarterly",3)))))} -> 45413 | O37: =IF(Tb_Data[[#This Row],[Expiration_date]]<C̳álculos!$I$6,"",Tb_Data[[#This Row],[Expiration_date]]) | P37: =DATEVALUE(_xlfn.CONCAT("01/",MONTH(Tb_Data[[#This Row],[Start Date]]),"/",YEAR(Tb_Data[[#This Row],[Start Date]]))) -> 45383 | Q37: =IF(Tb_Data[[#This Row],[Auto Renewal]]="yes","Auto","Manual") -> Auto
A38: 3267 | B38: Bruno Cavalheiro | C38: Ultimate | D38: 45384 | E38: No | F38: 15 | G38: Quarterly | H38: Yes | I38: 30 | J38: Yes | K38: 20 | L38: 7 | M38: 58 | N38: {=DATEVALUE(_xlfn.CONCAT("01/", MONTH(EDATE(Tb_Data[[#This Row],[Start Date]],_xlfn.IFS(Tb_Data[[#This Row],[Subscription Type]]="Monthly",1,Tb_Data[[#This Row],[Subscription Type]]="Annual",12,Tb_Data[[#This Row],[Subscription Type]]="Quarterly",3))),"/", YEAR(EDATE(Tb_Data[[#This Row],[Start Date]],_xlfn.IFS(Tb_Data[[#This Row],[Subscription Type]]="Monthly",1,Tb_Data[[#This Row],[Subscription Type]]="Annual",12,Tb_Data[[#This Row],[Subscription Type]]="Quarterly",3)))))} -> 45474 | O38: =IF(Tb_Data[[#This Row],[Expiration_date]]<C̳álculos!$I$6,"",Tb_Data[[#This Row],[Expiration_date]]) | P38: =DATEVALUE(_xlfn.CONCAT("01/",MONTH(Tb_Data[[#This Row],[Start Date]]),"/",YEAR(Tb_Data[[#This Row],[Start Date]]))) -> 45383 | Q38: =IF(Tb_Data[[#This Row],[Auto Renewal]]="yes","Auto","Manual") -> Manual
A39: 3268 | B39: Carla Dias | C39: Standard | D39: 45385 | E39: Yes | F39: 10 | G39: Annual | H39: No | I39: - | J39: Yes | K39: 20 | L39: 10 | M39: 20 | N39: {=DATEVALUE(_xlfn.CONCAT("01/", MONTH(EDATE(Tb_Data[[#This Row],[Start Date]],_xlfn.IFS(Tb_Data[[#This Row],[Subscription Type]]="Monthly",1,Tb_Data[[#This Row],[Subscription Type]]="Annual",12,Tb_Data[[#This Row],[Subscription Type]]="Quarterly",3))),"/", YEAR(EDATE(Tb_Data[[#This Row],[Start Date]],_xlfn.IFS(Tb_Data[[#This Row],[Subscription Type]]="Monthly",1,Tb_Data[[#This Row],[Subscription Type]]="Annual",12,Tb_Data[[#This Row],[Subscription Type]]="Quarterly",3)))))} -> 45748 | O39: =IF(Tb_Data[[#This Row],[Expiration_date]]<C̳álculos!$I$6,"",Tb_Data[[#This Row],[Expiration_date]]) -> 45748 | P39: =DATEVALUE(_xlfn.CONCAT("01/",MONTH(Tb_Data[[#This Row],[Start Date]]),"/",YEAR(Tb_Data[[#This Row],[Start Date]]))) -> 45383 | Q39: =IF(Tb_Data[[#This Row],[Auto Renewal]]="yes","Auto","Manual") -> Auto
A40: 3269 | B40: Diego Fontes | C40: Core | D40: 45386 | E40: No | F40: 5 | G40: Quarterly | H40: No | I40: - | J40: No | K40: 0 | L40: 1 | M40: 4 | N40: {=DATEVALUE(_xlfn.CONCAT("01/", MONTH(EDATE(Tb_Data[[#This Row],[Start Date]],_xlfn.IFS(Tb_Data[[#This Row],[Subscription Type]]="Monthly",1,Tb_Data[[#This Row],[Subscription Type]]="Annual",12,Tb_Data[[#This Row],[Subscription Type]]="Quarterly",3))),"/", YEAR(EDATE(Tb_Data[[#This Row],[Start Date]],_xlfn.IFS(Tb_Data[[#This Row],[Subscription Type]]="Monthly",1,Tb_Data[[#This Row],[Subscription Type]]="Annual",12,Tb_Data[[#This Row],[Subscription Type]]="Quarterly",3)))))} -> 45474 | O40: =IF(Tb_Data[[#This Row],[Expiration_date]]<C̳álculos!$I$6,"",Tb_Data[[#This Row],[Expiration_date]]) | P40: =DATEVALUE(_xlfn.CONCAT("01/",MONTH(Tb_Data[[#This Row],[Start Date]]),"/",YEAR(Tb_Data[[#This Row],[Start Date]]))) -> 45383 | Q40: =IF(Tb_Data[[#This Row],[Auto Renewal]]="yes","Auto","Manual") -> Manual
...

Sheet C̳álculos
B3: Visões de Negócios
I6: =EOMONTH(D̳ashboard!B5,-1)+1 -> 45627
B9: Rótulos de Linha | C9: Soma de Subscription Price | F9: Rótulos de Linha | G9: Acquisition | I9: Rótulos de Linha | J9: Acquisition | L9: Rótulos de Linha | M9: Soma de Total Value | O9: Rótulos de Linha | P9: Soma de EA Play Season Pass | R9: Rótulos de Linha | S9: Soma de Minecraft Season Pass Price | U9: Soma de Coupon Value
B10: Core | C10: 505 | F10: 45292 | G10: 2 | I10: 45627 | J10: 23 | L10: Core | M10: 444 | O10: No | P10: 0 | R10: No | S10: 0 | U10: 2122
B11: Standard | C11: 960 | F11: 45323 | G11: 2 | I11: 45658 | J11: 16 | L11: Standard | M11: 1801 | O11: Yes | P11: 2940 | R11: Yes | S11: 3880
B12: Ultimate | C12: 1470 | F12: 45352 | G12: 31 | I12: 45689 | J12: 9 | L12: Ultimate | M12: 5388 | O12: Total Geral | P12: 2940 | R12: Total Geral | S12: 3880
B13: Total Geral | C13: 2935 | F13: 45383 | G13: 30 | I13: 45717 | J13: 11 | L13: Total Geral | M13: 7633
F14: 45413 | G14: 31 | I14: 45748 | J14: 7
F15: 45444 | G15: 30 | I15: 45778 | J15: 8
F16: 45474 | G16: 31 | I16: 45809 | J16: 7
F17: 45505 | G17: 31 | I17: 45839 | J17: 7
B18: Rótulos de Linha | C18: Contagem de Name | F18: 45536 | G18: 30 | I18: 45870 | J18: 8
B19: Core | C19: 101 | F19: 45566 | G19: 31 | I19: 45901 | J19: 7
B20: Standard | C20: 96 | F20: 45597 | G20: 30 | I20: 45931 | J20: 8
B21: Ultimate | C21: 98 | F21: 45627 | G21: 16 | I21: 45962 | J21: 7
B22: Total Geral | C22: 295 | F22: Total Geral | G22: 295 | I22: 45992 | J22: 4
I23: Total Geral | J23: 122

Sheet D̳ashboard
F1: X-Box Subscription Data
B5: 45651
F7: Subscription Total Value | J7: EA Play Season Pass | O7: Minecraft Season Pass | S7: Coupons
F8: =GETPIVOTDATA("Total Value",C̳álculos!$L$9) -> 7633 | J8: =GETPIVOTDATA("EA Play Season Pass Price",C̳álculos!$O$9) -> 2940 | O8: =GETPIVOTDATA("Minecraft Season Pass Price",C̳álculos!$R$9) -> 3880 | S8: =-GETPIVOTDATA("Coupon Value",C̳álculos!$U$9) -> -2122
F11: Subscription Type | M11: Subscription Sales Growth
F24: Expiration Subscriptions
B34: Period from
B35: =_xlfn.CONCAT(TEXT(MIN(Tb_Data[Start Date]),"dd/mm/aaa")," to ",TEXT(MAX(Tb_Data[Start Date]),"dd/mm/aaa")) -> 01/01/2024 to 16/12/2024
